<?xml version="1.0" encoding="utf-8"?>
<!-- This is the URDF file for FAIRSPACE AISAT -->
<!-- This is a public version under MIT 2.0 Licenses-->
<!-- Credit to R.B. Ashith Shyam, Daniel Z. Hao, and Arunkumar Rathinam -->
<!-- =================================================================================== -->
<!-- |    This document was autogenerated by xacro from free_floating_7dof.urdf.xacro  | -->
<!-- |    EDITING THIS FILE BY HAND IS NOT RECOMMENDED                                 | -->
<!-- =================================================================================== -->
<robot name="AISAT">
  <!-- 
  <gazebo>
    <plugin name="gazebo_ros_control" filename="libgazebo_ros_control.so">
      <robotNamespace>/</robotNamespace>
    </plugin>
  </gazebo> -->
  <material name="blue">
    <color rgba="0 0 0.8 1"/>
  </material>
  <material name="white">
    <color rgba="1 1 0.6 1"/>
  </material>
  <link name="spacecraft_link0">
    <visual>
      <material name="white"/>
      <geometry>
        <box size="2.1 2.1 2.1"/>
      </geometry>
    </visual>
    <collision>
      <geometry>
        <box size="2.1 2.1 2.1"/>
      </geometry>
    </collision>
    <inertial>
      <mass value="200.0"/>
      <inertia ixx="1400.0" ixy="0.0" ixz="0.0" iyy="1400.0" iyz="0.0" izz="2040.0"/>
    </inertial>
  </link>
  <link name="spacecraft_link1">
    <visual>
      <material name="blue"/>
      <geometry>
        <cylinder length="0.5" radius="0.04"/>
      </geometry>
      <origin rpy="0 0 0" xyz="0 0 0.27"/>
    </visual>
    <collision>
      <geometry>
        <cylinder length="0.5" radius="0.04"/>
      </geometry>
    </collision>
    <inertial>
      <mass value="20.0"/>
      <inertia ixx="0.1" ixy="0.0" ixz="0.0" iyy="0.1" iyz="0.0" izz="0.1"/>
    </inertial>
  </link>
  <joint name="spacecraft_joint1" type="revolute">
    <safety_controller k_position="100.0" k_velocity="40.0" soft_lower_limit="-2.8973" soft_upper_limit="2.8973"/>
    <origin rpy="-1.57079632679 0 -0.785398163397" xyz="1.05 1.05 0"/>
    <parent link="spacecraft_link0"/>
    <child link="spacecraft_link1"/>
    <axis xyz="0 0 1"/>
    <limit effort="87" lower="-2.8973" upper="2.8973" velocity="2.1750"/>
  </joint>
  <link name="spacecraft_link2">
    <visual>
      <material name="blue"/>
      <geometry>
        <cylinder length="0.9" radius="0.04"/>
      </geometry>
      <origin rpy="0 1.57079632679 0" xyz="0.45 0 0"/>
    </visual>
    <collision>
      <geometry>
        <cylinder length="0.9" radius="0.04"/>
      </geometry>
    </collision>
    <inertial>
      <mass value="30.0"/>
      <inertia ixx="0.25" ixy="0.0" ixz="0.0" iyy="25.0" iyz="0.0" izz="25.0"/>
    </inertial>
  </link>
  <joint name="spacecraft_joint2" type="revolute">
    <safety_controller k_position="100.0" k_velocity="40.0" soft_lower_limit="-1.7628" soft_upper_limit="1.7628"/>
    <origin rpy="1.57079632679 3.92699081699 0" xyz="0 0 0.6"/>
<!--<origin rpy="1.57079632679 -3.92699081699 0" xyz="0 0 0.6"/>-->
    <parent link="spacecraft_link1"/>
    <child link="spacecraft_link2"/>
    <axis xyz="0 0 1"/>
    <limit effort="87" lower="-1.7628" upper="1.7628" velocity="2.1750"/>
  </joint>
  <link name="spacecraft_link3">
    <visual>
      <material name="blue"/>
      <geometry>
        <cylinder length="0.9" radius="0.04"/>
      </geometry>
      <origin rpy="0 1.57079632679 0" xyz="0.45 0 0"/>
    </visual>
    <collision>
      <geometry>
        <cylinder length="0.9" radius="0.04"/>
      </geometry>
    </collision>
    <inertial>
      <mass value="30.0"/>
      <inertia ixx="0.25" ixy="0.0" ixz="0.0" iyy="25.0" iyz="0.0" izz="25.0"/>
    </inertial>
  </link>
  <joint name="spacecraft_joint3" type="revolute">
    <safety_controller k_position="100.0" k_velocity="40.0" soft_lower_limit="-1.7628" soft_upper_limit="1.7628"/>
    <origin rpy="1.57079632679 0 0" xyz="1.0 0 0"/>
    <parent link="spacecraft_link2"/>
    <child link="spacecraft_link3"/>
    <axis xyz="0 0 1"/>
    <limit effort="87" lower="-1.7628" upper="1.7628" velocity="2.1750"/>
  </joint>
  <link name="spacecraft_link4">
    <visual>
      <material name="blue"/>
      <geometry>
        <cylinder length="0.8" radius="0.04"/>
      </geometry>
      <origin rpy="0 1.57079632679 0" xyz="0.4 0 0"/>
    </visual>
    <collision>
      <geometry>
        <cylinder length="0.8" radius="0.04"/>
      </geometry>
    </collision>
    <inertial>
      <mass value="20.0"/>
      <inertia ixx="0.25" ixy="0.0" ixz="0.0" iyy="25.0" iyz="0.0" izz="25.0"/>
    </inertial>
  </link>
  <joint name="spacecraft_joint4" type="revolute">
    <safety_controller k_position="100.0" k_velocity="40.0" soft_lower_limit="-1.7628" soft_upper_limit="1.7628"/>
    <origin rpy="-1.57079632679 0 0" xyz="1.0 0 0"/>
    <parent link="spacecraft_link3"/>
    <child link="spacecraft_link4"/>
    <axis xyz="0 0 1"/>
    <limit effort="87" lower="-1.7628" upper="1.7628" velocity="2.1750"/>
  </joint>
  <link name="spacecraft_link5">
    <visual>
      <material name="blue"/>
      <geometry>
        <cylinder length="0.8" radius="0.04"/>
      </geometry>
      <origin rpy="0 1.57079632679 0" xyz="0.4 0 0"/>
    </visual>
    <collision>
      <geometry>
        <cylinder length="0.8" radius="0.04"/>
      </geometry>
    </collision>
    <inertial>
      <mass value="20.0"/>
      <inertia ixx="0.25" ixy="0.0" ixz="0.0" iyy="25.0" iyz="0.0" izz="25.0"/>
    </inertial>
  </link>
  <joint name="spacecraft_joint5" type="revolute">
    <safety_controller k_position="100.0" k_velocity="40.0" soft_lower_limit="-1.7628" soft_upper_limit="1.7628"/>
    <origin rpy="0 0 1.57079632679" xyz="0.9 0 0"/>
    <parent link="spacecraft_link4"/>
    <child link="spacecraft_link5"/>
    <axis xyz="0 0 1"/>
    <limit effort="87" lower="-1.7628" upper="1.7628" velocity="2.1750"/>
  </joint>
  <link name="spacecraft_link6">
    <visual>
      <material name="blue"/>
      <geometry>
        <cylinder length="0.8" radius="0.04"/>
      </geometry>
      <origin rpy="1.57079632679 0 0" xyz="0  0.4 0"/>
    </visual>
    <collision>
      <geometry>
        <cylinder length="0.8" radius="0.04"/>
      </geometry>
    </collision>
    <inertial>
      <mass value="20.0"/>
      <inertia ixx="0.25" ixy="0.0" ixz="0.0" iyy="25.0" iyz="0.0" izz="25.0"/>
    </inertial>
  </link>
  <joint name="spacecraft_joint6" type="revolute">
    <safety_controller k_position="100.0" k_velocity="40.0" soft_lower_limit="-1.7628" soft_upper_limit="1.7628"/>
    <origin rpy="-1.57079632679 -1.57079632679 0" xyz="0.9 0 0"/>
    <parent link="spacecraft_link5"/>
    <child link="spacecraft_link6"/>
    <axis xyz="0 0 1"/>
    <limit effort="87" lower="-1.7628" upper="1.7628" velocity="2.1750"/>
  </joint>
  <link name="spacecraft_link7">
    <visual>
      <material name="blue"/>
      <geometry>
        <cylinder length="0.9" radius="0.04"/>
      </geometry>
      <origin rpy="0 0 1.57079632679" xyz="0 0 0.45"/>
    </visual>
    <collision>
      <geometry>
        <cylinder length="0.9" radius="0.04"/>
      </geometry>
    </collision>
    <inertial>
      <mass value="20.0"/>
      <inertia ixx="0.25" ixy="0.0" ixz="0.0" iyy="25.0" iyz="0.0" izz="25.0"/>
    </inertial>
  </link>
  <joint name="spacecraft_joint7" type="revolute">
    <safety_controller k_position="100.0" k_velocity="40.0" soft_lower_limit="-1.7628" soft_upper_limit="1.7628"/>
    <origin rpy="-1.57079632679 0 0" xyz="0 0.9 0"/>
    <parent link="spacecraft_link6"/>
    <child link="spacecraft_link7"/>
    <axis xyz="0 0 1"/>
    <limit effort="87" lower="-1.7628" upper="1.7628" velocity="2.1750"/>
  </joint>
  <joint name="spacecraft_hand_joint" type="fixed">
    <parent link="spacecraft_link7"/>
    <child link="spacecraft_hand"/>
    <origin rpy="0 0 0" xyz="0 0 0.9"/>
  </joint>
  <link name="spacecraft_hand">
    <visual>
      <geometry>
        <mesh filename="/home/ash/Ash/repo/ash_pybullet/free_floating/meshes/visual/hand.dae"/>
      </geometry>
    </visual>
    <collision>
      <geometry>
        <mesh filename="/home/ash/Ash/repo/ash_pybullet/free_floating/meshes/collision/hand.stl"/>
      </geometry>
    </collision>
  </link>
  <link name="spacecraft_leftfinger">
    <visual>
      <geometry>
        <mesh filename="/home/ash/Ash/repo/ash_pybullet/free_floating/meshes/visual/finger.dae"/>
      </geometry>
    </visual>
    <collision>
      <geometry>
        <mesh filename="/home/ash/Ash/repo/ash_pybullet/free_floating/meshes/collision/finger.stl"/>
      </geometry>
    </collision>
  </link>
  <link name="spacecraft_rightfinger">
    <visual>
      <origin rpy="0 0 3.14159265359" xyz="0 0 0"/>
      <geometry>
        <mesh filename="/home/ash/Ash/repo/ash_pybullet/free_floating/meshes/visual/finger.dae"/>
      </geometry>
    </visual>
    <collision>
      <origin rpy="0 0 3.14159265359" xyz="0 0 0"/>
      <geometry>
        <mesh filename="/home/ash/Ash/repo/ash_pybullet/free_floating/meshes/collision/finger.stl"/>
      </geometry>
    </collision>
  </link>
  <joint name="spacecraft_finger_joint1" type="prismatic">
    <parent link="spacecraft_hand"/>
    <child link="spacecraft_leftfinger"/>
    <origin rpy="0 0 0" xyz="0 0 0.0584"/>
    <axis xyz="0 1 0"/>
    <limit effort="20" lower="0.0" upper="0.04" velocity="0.2"/>
  </joint>
  <joint name="spacecraft_finger_joint2" type="prismatic">
    <parent link="spacecraft_hand"/>
    <child link="spacecraft_rightfinger"/>
    <origin rpy="0 0 0" xyz="0 0 0.0584"/>
    <axis xyz="0 -1 0"/>
    <limit effort="20" lower="0.0" upper="0.04" velocity="0.2"/>
    <mimic joint="spacecraft_finger_joint1"/>
  </joint>
</robot>
